Workbook

Sheet Cover
B4: ParrotEdu App - Test Case
B5: Initialized Date
B6: Author | C6: QA Team
B9: Info test (account/pass/... | C9: Tài khoản demo Free: 0909111111 / Pro: 0909222222 / Dùng thử: 0909333333
B13: Người Duyệt
B18: 1. Revision History
B20: Date (YYYY-MM-DD) | C20: Version | D20: Change Description | E20: Author

Sheet Ôn thi - Kho đề Parrot
B1: ParrotEdu App
A2: Test requirement | B2: Ôn thi - Kho đề Parrot
A3: TC_ID | B3: TC_PE_OnThiKhoDe
A4: Number of TCs | B4: Pass | C4: Fail | D4: N/A | E4: Pending | F4: Todo | G4: Retest
A5: =(COUNTIFS(A9:A88, "TC_*")*2) | B5: =COUNTIFS(I:J,"Pass") | C5: =COUNTIFS(I:J, "Fail") | D5: =COUNTIFS(I:J, "N/A") | E5: =COUNTIFS(I:J, "pending") | F5: =COUNTIFS(I:J, "todo") | G5: =COUNTIFS(I:J, "re-test")
I6: ACTUAL OUTPUT - 1 [Name] | L6: Note
A7: Test case ID | B7: Test Case Name (*) | C7: Precondition | D7: Detail Step | E7: Test Data | F7: Expected Result(*) | G7: Priority (*) | H7: TC Type (*) | I7: PC | K7: Execute Date
I8: Chrome | J8: Safari (MAC)
A9: I. Màn hình Danh sách đề (tab Kho đề Parrot)
A10: 1. Card "Tiếp tục bài đang làm dở" & label số lượng đề
A11: =IF(I11>0,$B$3&"_"&SUBTOTAL(3,$I$9:I11),"") | B11: Kiểm tra hiển thị card "Tiếp tục bài đang làm dở" khi có đề đang làm dở trong Kho đề | C11: 1. Profile đang đăng nhập có ít nhất 1 đề trong Kho đề Parrot đang ở trạng thái làm dở (đã bắt đầu, chưa nộp, thời gian đếm ngược vẫn còn) | D11: 1. Vào màn Ôn thi 2. Chọn tab Kho đề Parrot | F11: 2. Hiển thị card "Tiếp tục bài đang làm dở" ở đầu danh sách, gồm tên đề đang làm dở gần nhất và nút "Tiếp tục" | G11: High | H11: Function | I11: Todo | J11: Todo
A12: =IF(I12>0,$B$3&"_"&SUBTOTAL(3,$I$9:I12),"") | B12: Kiểm tra không hiển thị card "Tiếp tục bài đang làm dở" khi profile không có đề nào đang làm dở | C12: 1. Profile đang đăng nhập chưa làm đề nào hoặc đã nộp hết các đề đã làm trong Kho đề Parrot | D12: 1. Vào màn Ôn thi 2. Chọn tab Kho đề Parrot | F12: 2. Không hiển thị card "Tiếp tục bài đang làm dở" ở đầu danh sách | G12: Medium | H12: GUI | I12: Todo | J12: Todo
A13: =IF(I13>0,$B$3&"_"&SUBTOTAL(3,$I$9:I13),"") | B13: Kiểm tra card "Tiếp tục bài đang làm dở" chỉ hiển thị đúng 1 đề được làm dở gần nhất khi có nhiều đề đang làm dở cùng lúc | C13: 1. Profile đang đăng nhập có từ 2 đề trở lên đang ở trạng thái làm dở (chưa nộp, còn thời gian đếm ngược) | D13: 1. Vào màn Ôn thi 2. Chọn tab Kho đề Parrot 3. Quan sát tên đề hiển thị trên card "Tiếp tục bài đang làm dở" | F13: 3. Card chỉ hiển thị đúng 1 đề là đề được bắt đầu làm gần nhất (thời điểm bắt đầu làm mới nhất) | G13: Medium | H13: Function | I13: Todo | J13: Todo
A14: =IF(I14>0,$B$3&"_"&SUBTOTAL(3,$I$9:I14),"") | B14: Kiểm tra chọn nút "Tiếp tục" trên card điều hướng đến màn Chi tiết đề và giữ nguyên tiến trình bài làm dở | C14: 1. Đang ở tab Kho đề Parrot 2. Có card "Tiếp tục bài đang làm dở" hiển thị | D14: 1. Chọn nút "Tiếp tục" trên card | F14: 1. Hệ thống chuyển đến màn Chi tiết đề (màn làm bài) đúng đề đang làm dở, giữ nguyên các câu đã trả lời và thời gian đếm ngược còn lại trước đó | G14: High | H14: Function | I14: Todo | J14: Todo
A15: =IF(I15>0,$B$3&"_"&SUBTOTAL(3,$I$9:I15),"") | B15: Kiểm tra label "N đề" hiển thị đúng tổng số đề theo bộ lọc mặc định đang áp dụng | C15: 1. Đang ở tab Kho đề Parrot với bộ lọc mặc định (theo khối lớp của profile) | D15: 1. Quan sát label số lượng đề phía dưới card "Tiếp tục bài đang làm dở" | F15: 1. Label hiển thị đúng định dạng "N đề", với N bằng đúng tổng số đề công khai đang khớp bộ lọc hiện tại | G15: High | H15: Function | I15: Todo | J15: Todo
A16: =IF(I16>0,$B$3&"_"&SUBTOTAL(3,$I$9:I16),"") | B16: Kiểm tra label "N đề" cập nhật ngay khi áp dụng bộ lọc mới | C16: 1. Đang ở tab Kho đề Parrot, bộ lọc hiện tại đang áp dụng mặc định | D16: 1. Mở bottom sheet Lọc đề thi 2. Chọn "Thi học kỳ" ở tab Loại kỳ thi 3. Chọn Xác nhận | E16: Loại kỳ thi: Thi học kỳ | F16: 3. Label "N đề" cập nhật thành số lượng đề khớp đúng với bộ lọc "Thi học kỳ" vừa áp dụng | G16: Medium | H16: Function | I16: Todo | J16: Todo
A17: 2. Card đề thi - nội dung hiển thị & điều hướng
A18: =IF(I18>0,$B$3&"_"&SUBTOTAL(3,$I$9:I18),"") | B18: Kiểm tra danh sách đề hiển thị theo đúng thứ tự từ đề được tạo mới nhất đến cũ nhất | C18: 1. Có nhiều hơn 1 đề công khai khớp bộ lọc hiện tại | D18: 1. Vào tab Kho đề Parrot 2. Quan sát thứ tự các card đề trong danh sách | F18: 2. Danh sách đề được sắp xếp theo thứ tự đề tạo mới nhất hiển thị trên cùng, đề cũ hơn hiển thị bên dưới | G18: High | H18: Function | I18: Todo | J18: Todo
A19: =IF(I19>0,$B$3&"_"&SUBTOTAL(3,$I$9:I19),"") | B19: Kiểm tra card đề hiển thị đầy đủ Loại kỳ thi, Tên đề, Thời lượng (phút) và Tổng số câu đúng theo cấu hình trên CMS | C19: 1. Có đề công khai hiển thị trong danh sách, đã biết trước cấu hình trên CMS (vd: Thời lượng 90 phút, 40 câu) | D19: 1. Vào tab Kho đề Parrot 2. Quan sát nội dung card đề tương ứng | E19: Đề: "Đề thi thử vào 10 Sở DGDT TP Hà Nội (năm 2025)" - 90 phút - 40 câu | F19: 2. Card hiển thị đúng Loại kỳ thi (vd: Thi vào 10), Tên đề, dòng "90 phút - 40 câu" khớp dữ liệu đã cấu hình trên CMS | G19: Medium | H19: Function | I19: Todo | J19: Todo
A20: =IF(I20>0,$B$3&"_"&SUBTOTAL(3,$I$9:I20),"") | B20: Kiểm tra card đề được gắn Pro trên CMS hiển thị badge "Pro" | C20: 1. Có đề đã được gắn thuộc tính Pro trên CMS và đang công khai | D20: 1. Vào tab Kho đề Parrot 2. Quan sát card của đề Pro | F20: 2. Card hiển thị badge "Pro" cạnh Loại kỳ thi | G20: Medium | H20: GUI | I20: Todo | J20: Todo
A21: =IF(I21>0,$B$3&"_"&SUBTOTAL(3,$I$9:I21),"") | B21: Kiểm tra card đề Free (không gắn Pro trên CMS) không hiển thị badge "Pro" | C21: 1. Có đề không gắn thuộc tính Pro trên CMS và đang công khai | D21: 1. Vào tab Kho đề Parrot 2. Quan sát card của đề Free | F21: 2. Card không hiển thị badge "Pro" | G21: Low | H21: GUI | I21: Todo | J21: Todo
A22: =IF(I22>0,$B$3&"_"&SUBTOTAL(3,$I$9:I22),"") | B22: Kiểm tra card đề chưa từng làm lần nào không hiển thị bất kỳ trạng thái làm bài nào | C22: 1. Có đề công khai mà profile hiện tại chưa từng bắt đầu làm lần nào | D22: 1. Vào tab Kho đề Parrot 2. Quan sát card của đề chưa từng làm | F22: 2. Card không hiển thị trạng thái "Đang làm dở" hay "Đã hoàn thành", không hiển thị điểm số | G22: Medium | H22: GUI | I22: Todo | J22: Todo
A23: =IF(I23>0,$B$3&"_"&SUBTOTAL(3,$I$9:I23),"") | B23: Kiểm tra card đề đang làm dở hiển thị trạng thái "Đang làm dở" và không hiển thị điểm số | C23: 1. Có đề đang ở trạng thái làm dở (chưa nộp, còn thời gian) | D23: 1. Vào tab Kho đề Parrot 2. Quan sát card của đề đang làm dở | F23: 2. Card hiển thị badge trạng thái "Đang làm dở", không hiển thị điểm số | G23: Medium | H23: GUI | I23: Todo | J23: Todo
A24: =IF(I24>0,$B$3&"_"&SUBTOTAL(3,$I$9:I24),"") | B24: Kiểm tra card đề đã hoàn thành và không có phiên làm dở nào hiển thị trạng thái "Đã hoàn thành" kèm điểm số gần nhất | C24: 1. Có đề đã được nộp bài hoàn chỉnh, không có phiên làm dở nào khác đang chạy | D24: 1. Vào tab Kho đề Parrot 2. Quan sát card của đề đã hoàn thành | F24: 2. Card hiển thị "Điểm số: X.X" và badge trạng thái "Đã hoàn thành" | G24: Medium | H24: GUI | I24: Todo | J24: Todo
A25: =IF(I25>0,$B$3&"_"&SUBTOTAL(3,$I$9:I25),"") | B25: Kiểm tra chọn 1 card đề bất kỳ điều hướng đến màn Thông tin đề | C25: 1. Đang ở tab Kho đề Parrot, có ít nhất 1 card đề hiển thị | D25: 1. Chọn vào 1 card đề trong danh sách | F25: 1. Hệ thống chuyển đến màn Thông tin đề tương ứng với đề vừa chọn | G25: High | H25: Function | I25: Todo | J25: Todo
A26: II. Bottom sheet Tìm đề thi
A27: 1. Tìm kiếm đề thi trong Kho đề Parrot
A28: =IF(I28>0,$B$3&"_"&SUBTOTAL(3,$I$9:I28),"") | B28: Kiểm tra chọn icon Tìm kiếm mở bottom sheet "Tìm đề thi" | C28: 1. Đang ở tab Kho đề Parrot | D28: 1. Chọn icon Tìm kiếm (kính lúp) | F28: 1. Bottom sheet "Tìm đề thi" mở lên, hiển thị dòng phụ "Tìm trong Kho đề ParrotEdu" và ô nhập liệu để trống | G28: High | H28: Function | I28: Todo | J28: Todo
A29: =IF(I29>0,$B$3&"_"&SUBTOTAL(3,$I$9:I29),"") | B29: Kiểm tra trạng thái mặc định của bottom sheet Tìm đề thi khi chưa nhập nội dung | C29: 1. Vừa mở bottom sheet Tìm đề thi, ô tìm kiếm chưa nhập gì | D29: 1. Quan sát nội dung bottom sheet | F29: 1. Ô tìm kiếm hiển thị placeholder "Nhập tên đề thi", bên dưới hiển thị text hướng dẫn "Nhập tên đề thi để tìm kiếm", không hiển thị danh sách kết quả | G29: Low | H29: GUI | I29: Todo | J29: Todo
A30: =IF(I30>0,$B$3&"_"&SUBTOTAL(3,$I$9:I30),"") | B30: Kiểm tra tìm kiếm theo tên đề và bấm Enter trả về đúng danh sách kết quả tương đối theo tên đề | C30: 1. Đang mở bottom sheet Tìm đề thi 2. Có ít nhất 1 đề công khai trong Kho đề Parrot chứa ký tự "e" trong tên | D30: 1. Nhập "e" vào ô tìm kiếm 2. Bấm Enter trên bàn phím | E30: Từ khóa: e | F30: 2. Hệ thống hiển thị danh sách các đề có tên chứa "e", ví dụ "Thi thử vào 10 - Hà Nội 2025 - Đề 3", "Thi thử vào 10 - TP.HCM 2025 - Đề 1", "Đề tham khảo vào 10 - Hà Nội 2024" | G30: High | H30: Function | I30: Todo | J30: Todo
A31: =IF(I31>0,$B$3&"_"&SUBTOTAL(3,$I$9:I31),"") | B31: Kiểm tra số lượng kết quả tìm kiếm hiển thị đúng định dạng "N kết quả" | C31: 1. Đã thực hiện tìm kiếm với từ khóa có kết quả trả về | D31: 1. Nhập từ khóa hợp lệ và bấm Enter | E31: Từ khóa: e | F31: 1. Hiển thị "3 kết quả" khớp đúng số lượng đề trả về | G31: Medium | H31: Function | I31: Todo | J31: Todo
A32: =IF(I32>0,$B$3&"_"&SUBTOTAL(3,$I$9:I32),"") | B32: Kiểm tra mỗi dòng kết quả tìm kiếm hiển thị đúng Tên đề và subtext "Thời lượng - Tổng số câu" | C32: 1. Đã thực hiện tìm kiếm có kết quả trả về | D32: 1. Quan sát 1 dòng kết quả bất kỳ trong danh sách | E32: Từ khóa: e | F32: 1. Dòng kết quả hiển thị Tên đề ở dòng trên, subtext "90 phút - 40 câu" ở dòng dưới khớp dữ liệu thực tế của đề | G32: Medium | H32: GUI | I32: Todo | J32: Todo
A33: =IF(I33>0,$B$3&"_"&SUBTOTAL(3,$I$9:I33),"") | B33: Kiểm tra tìm kiếm với từ khóa không khớp đề nào hiển thị text "Không tìm thấy đề phù hợp" | C33: 1. Đang mở bottom sheet Tìm đề thi | D33: 1. Nhập từ khóa không trùng tên bất kỳ đề nào 2. Bấm Enter | E33: Từ khóa: zzxyzkhongtontai | F33: 2. Hệ thống hiển thị text "Không tìm thấy đề phù hợp", không hiển thị danh sách kết quả | G33: Medium | H33: Function | I33: Todo | J33: Todo
A34: =IF(I34>0,$B$3&"_"&SUBTOTAL(3,$I$9:I34),"") | B34: Kiểm tra chọn 1 dòng kết quả tìm kiếm điều hướng đến màn Thông tin đề tương ứng | C34: 1. Đã tìm kiếm và có danh sách kết quả hiển thị | D34: 1. Chọn vào 1 dòng kết quả bất kỳ | E34: Từ khóa: e | F34: 1. Hệ thống chuyển đến màn Thông tin đề của đề vừa chọn | G34: High | H34: Function | I34: Todo | J34: Todo
A35: =IF(I35>0,$B$3&"_"&SUBTOTAL(3,$I$9:I35),"") | B35: Kiểm tra phạm vi tìm kiếm là toàn bộ đề trong tab Kho đề Parrot, không bị giới hạn bởi bộ lọc Lớp/Loại kỳ thi đang áp dụng | C35: 1. Bộ lọc hiện tại đang chọn Lớp 9 (không khớp 1 đề X thuộc Lớp 6) 2. Đề X đang công khai và có tên chứa từ khóa sẽ tìm | D35: 1. Mở bottom sheet Tìm đề thi 2. Nhập từ khóa khớp tên đề X 3. Bấm Enter | E35: Từ khóa: tên đề X (thuộc Lớp 6) | F35: 3. Kết quả tìm kiếm vẫn hiển thị đề X dù đề này không khớp bộ lọc Lớp 9 đang áp dụng ở danh sách chính | G35: Medium | H35: Function | I35: Todo | J35: Todo
A36: =IF(I36>0,$B$3&"_"&SUBTOTAL(3,$I$9:I36),"") | B36: Kiểm tra nút xóa nội dung trong ô tìm kiếm | C36: 1. Đang mở bottom sheet Tìm đề thi, đã nhập nội dung vào ô tìm kiếm | D36: 1. Nhập "e" vào ô tìm kiếm 2. Chọn icon xóa (x) trong ô tìm kiếm | E36: Từ khóa: e | F36: 2. Nội dung ô tìm kiếm được xóa hết, danh sách kết quả ẩn đi, quay về trạng thái mặc định (hiển thị text hướng dẫn) | G36: Low | H36: GUI | I36: Todo | J36: Todo
A37: =IF(I37>0,$B$3&"_"&SUBTOTAL(3,$I$9:I37),"") | B37: Kiểm tra đóng bottom sheet Tìm đề thi bằng icon X ở góc phải | C37: 1. Đang mở bottom sheet Tìm đề thi | D37: 1. Chọn icon X ở góc trên bên phải bottom sheet | F37: 1. Bottom sheet đóng lại, quay về màn danh sách đề, không áp dụng tìm kiếm nào | G37: Low | H37: GUI | I37: Todo | J37: Todo
A38: =IF(I38>0,$B$3&"_"&SUBTOTAL(3,$I$9:I38),"") | B38: Kiểm tra ô tìm kiếm không bắt buộc nhập, có thể đóng bottom sheet khi để trống | C38: 1. Đang mở bottom sheet Tìm đề thi, chưa nhập gì vào ô tìm kiếm | D38: 1. Chọn icon X để đóng bottom sheet mà không nhập từ khóa | F38: 1. Bottom sheet đóng bình thường, không hiển thị lỗi bắt buộc nhập liệu | G38: Low | H38: GUI | I38: Todo | J38: Todo
A39: =IF(I39>0,$B$3&"_"&SUBTOTAL(3,$I$9:I39),"") | B39: Kiểm tra tìm kiếm với từ khóa có khoảng trắng đầu/cuối vẫn trả về đúng kết quả tương đối (hệ thống tự trim) | C39: 1. Đang mở bottom sheet Tìm đề thi 2. Có đề tên chứa từ khóa "Hà Nội" | D39: 1. Nhập " Hà Nội " (có khoảng trắng đầu/cuối) vào ô tìm kiếm 2. Bấm Enter | E39: Từ khóa: " Hà Nội " | F39: 2. Hệ thống tự loại bỏ khoảng trắng thừa và trả về đúng danh sách các đề có tên chứa "Hà Nội" | G39: Medium | H39: Function | I39: Todo | J39: Todo
A40: III. Bottom sheet Lọc đề thi
...

Sheet Summary TCs
C1: [Link CMS / hệ thống test] | F1: [Tên dự án]
C3: Categories | D3: Test Case Overview
B4: STT | D4: #TC | E4: Pass | F4: Fail | G4: N/A | H4: Pending | I4: Todo | J4: Status Test | K4: Người test | L4: Note
D5: =D7 | E5: =E7 | F5: =F7 | G5: =G7 | H5: =H7 | I5: =I7
B6: 1 | C6: Ôn thi - Kho đề Parrot | D6: ='Ôn thi - Kho đề Parrot'!A5 | E6: ='Ôn thi - Kho đề Parrot'!B5 | F6: ='Ôn thi - Kho đề Parrot'!C5 | G6: ='Ôn thi - Kho đề Parrot'!D5 | H6: ='Ôn thi - Kho đề Parrot'!E5 | I6: ='Ôn thi - Kho đề Parrot'!F5 | J6: Todo
C7: Total | D7: =SUM(D6:D6) | E7: =SUM(E6:E6) | F7: =SUM(F6:F6) | G7: =SUM(G6:G6) | H7: =SUM(H6:H6) | I7: =SUM(I6:I6)
C8: % | E8: =IFERROR(E7/D7,0) | F8: =IFERROR(F7/D7,0) | G8: =IFERROR(G7/D7,0) | H8: =IFERROR(H7/D7,0) | I8: =IFERROR(I7/D7,0)

Sheet Glossary
B1: STT | C1: Phân loại | D1: Thật ngữ sử dụng | E1: Giải nghĩa | F1: Đối tượng sử dụng | G1: Ghi chú
B2: 1 | D2: Status Test | E2: Trạng thái test | F2: QA/QC/Tester
B3: =B2+B2 | C3: Status Test | D3: Todo | E3: Sẵn sàng test | F3: QA/QC/Tester
B4: =B3+1 | D4: Doing | E4: Đang test | F4: QA/QC/Tester
B5: =B4+1 | D5: Pass | E5: Đã pass | F5: QA/QC/Tester
B6: =B5+1 | D6: Fail | E6: Có lỗi - log lỗi | F6: QA/QC/Tester
B7: =B6+1 | D7: Pending | E7: Dừng test do chưa đủ điều kiện, dữ kiện/ kịch bản thiết sót/ chờ xác nhận | F7: QA/QC/Tester
B8: =B7+1 | D8: Re-Test | E8: Cần test lại sau quá trình Dev fixed | F8: QA/QC/Tester
B9: =B8+1 | D9: N/A | E9: Không test - do không trong scope test | F9: QA/QC/Tester
B10: =B9+1 | D10: Priority | E10: Mức độ ưu tiên của test case | F10: QA/QC/Tester
B11: =B10+1 | C11: Priority | D11: High | E11: Là những TCs là chức năng chính và happy cases | F11: QA/QC/Tester
B12: =B11+1 | D12: Medium | E12: Là những TCs là chức năng validate | F12: QA/QC/Tester
B13: =B12+1 | D13: Low | E13: Là những TCs là check giao diện | F13: QA/QC/Tester
B14: =B13+1 | D14: Precondition | E14: Tiền điều kiện - Điều kiện này cần có để thực hiện được ý nghĩa test case đưa ra | F14: QA/QC/Tester
B15: =B14+1 | D15: Test data | E15: Dữ liệu nhập vào test - tương ứng với mỗi trường thông tin | F15: QA/QC/Tester
B16: =B15+1 | D16: Untested | E16: Chưa được kiểm tra | F16: QA/QC/Tester
B17: =B16+1 | D17: Next Release/Next Version | E17: Phiên bản tiếp theo | F17: QA/QC/Tester/Dev
B18: =B17+1 | D18: Resolved | E18: Đã giải quyết - thường dùng diễn đạt những Q&A đã giải quyết | F18: QA/QC/Tester/Dev
B19: =B18+1 | D19: Validate | E19: Kiểm tra xác nhận hợp lệ - không hợp lệ ; Xác nhận với mỗi field | F19: QA/QC/Tester/Dev
B20: =B19+1
B21: =B20+1
B22: =B21+1

Sheet  Data
C1: Status | E1: Priority | F1: TC Type
C2: Todo | E2: High | F2: Function
C3: Doing | E3: Medium | F3: GUI
C4: Pass | E4: Low | F4: Others
C5: Fail
C6: Pending
C7: Re-Test
C8: N/A
