Workbook

Sheet Cover
B4: Parrot App - Ôn thi - Test Case
B5: Initialized Date
B6: Author | C6: QA Team
B9: Info test (account/pass/... | C9: Tài khoản HS Free/Pro/Dùng thử có lớp được giáo viên giao đề ôn thi
B13: Người Duyệt
B18: 1. Revision History
B20: Date (YYYY-MM-DD) | C20: Version | D20: Change Description | E20: Author

Sheet Danh sách đề (Đề thầy cô giao)
B1: Parrot App - Ôn thi
A2: Test requirement | B2: Danh sách đề (Đề thầy cô giao)
A3: TC_ID | B3: TC_APP_OnThi_DanhSachDe
A4: Number of TCs | B4: Pass | C4: Fail | D4: N/A | E4: Pending | F4: Todo | G4: Retest
A5: =(COUNTIFS(A9:A67,"TC_*")*2) -> 84 | B5: =COUNTIFS(I:J,"Pass") -> 71 | C5: =COUNTIFS(I:J,"Fail") -> 0 | D5: =COUNTIFS(I:J,"N/A") -> 0 | E5: =COUNTIFS(I:J,"pending") -> 1 | F5: =COUNTIFS(I:J,"todo") -> 12 | G5: =COUNTIFS(I:J,"re-test") -> 0
I6: ACTUAL OUTPUT - 1 [Name] | L6: Ảnh pass | M6: Note
A7: Test case ID | B7: Test Case Name (*) | C7: Precondition | D7: Detail Step | E7: Test Data | F7: Expected Result(*) | G7: Priority (*) | H7: TC Type (*) | I7: App | K7: Execute Date
I8: Android | J8: IOS
A9: I. Màn hình Danh sách đề thầy cô giao
A10: 1. Label Số lượng đề & Dropdown Thời gian giao đề
A11: =IF(I11>0,$B$3&"_"&SUBTOTAL(3,$I$9:I11),"") -> TC_APP_OnThi_DanhSachDe_1 | B11: Kiểm tra mặc định Dropdown Thời gian giao đề chọn '2 tuần gần nhất' khi vào màn lần đầu | C11: 1. Tài khoản HS đã đăng nhập, lớp đang tham gia đã được giáo viên giao ít nhất 1 đề ôn thi 2. Chưa từng vào màn Danh sách đề thầy cô giao trong phiên này | D11: 1. Vào tab Ôn thi 2. Chọn tab 'Đề thầy cô giao' | F11: 2. Dropdown Thời gian giao đề hiển thị mặc định '2 tuần gần nhất'; danh sách đề hiển thị đúng các đề được giao trong 2 tuần gần nhất | G11: High | H11: Function | I11: Pass | J11: Pass | L11: https://prnt.sc/Vu8070iZBVm6
A12: =IF(I12>0,$B$3&"_"&SUBTOTAL(3,$I$9:I12),"") -> TC_APP_OnThi_DanhSachDe_2 | B12: Kiểm tra Label Số lượng đề hiển thị đúng tổng số đề theo bộ lọc thời gian đang chọn | C12: 1. Lớp HS đang tham gia có 6 đề được giao trong 2 tuần gần nhất và 9 đề trong 1 tháng gần nhất | D12: 1. Vào màn Danh sách đề thầy cô giao (bộ lọc mặc định '2 tuần gần nhất') 2. Quan sát Label số lượng đề 3. Đổi bộ lọc sang '1 tháng gần nhất' 4. Quan sát lại Label số lượng đề | F12: 2. Label hiển thị '6 đề' 4. Label cập nhật thành '9 đề' | G12: High | H12: Function | I12: Pass | J12: Pass | L12: https://prnt.sc/voHnd_CIZV5O https://prnt.sc/8XLs4CZIY-6J
A13: =IF(I13>0,$B$3&"_"&SUBTOTAL(3,$I$9:I13),"") -> TC_APP_OnThi_DanhSachDe_3 | B13: Kiểm tra đổi bộ lọc sang '1 tháng gần nhất' cập nhật đúng danh sách đề hiển thị | C13: 1. Lớp HS đang tham gia có đề được giao cách đây 3 tuần (nằm ngoài '2 tuần gần nhất' nhưng trong '1 tháng gần nhất') | D13: 1. Vào màn Danh sách đề thầy cô giao 2. Xác nhận đề giao cách đây 3 tuần không hiển thị ở bộ lọc mặc định 3. Mở Dropdown Thời gian giao đề, chọn '1 tháng gần nhất' | F13: 2. Đề giao cách đây 3 tuần không xuất hiện trong danh sách 3. Danh sách cập nhật ngay, hiển thị thêm đề giao cách đây 3 tuần | G13: High | H13: Function | I13: Pass | J13: Pass | L13: https://prnt.sc/q-K6k_eYVZXz https://prnt.sc/cYA2nMCQ7qww
A14: =IF(I14>0,$B$3&"_"&SUBTOTAL(3,$I$9:I14),"") -> TC_APP_OnThi_DanhSachDe_4 | B14: Kiểm tra hiển thị khi không có đề nào trong khoảng thời gian đang lọc | C14: 1. Lớp HS đang tham gia không có đề nào được giao trong 2 tuần gần nhất (nhưng có đề nằm ngoài khoảng, ví dụ trong 1 tháng gần nhất) | D14: 1. Vào màn Danh sách đề thầy cô giao với bộ lọc mặc định '2 tuần gần nhất' | F14: 1. Label hiển thị '0 đề' và khu vực danh sách hiển thị text thông báo trạng thái rỗng (vd: 'Không có đề nào trong khoảng thời gian này'), không hiển thị card đề nào | G14: Medium | H14: Function | I14: Pass | J14: Pass | L14: https://prnt.sc/sreE6zwoP_rt https://prnt.sc/192GTlhYcrZ3
A15: =IF(I15>0,$B$3&"_"&SUBTOTAL(3,$I$9:I15),"") -> TC_APP_OnThi_DanhSachDe_5 | B15: Kiểm tra hiển thị text thông báo khi lớp chưa từng được giáo viên giao đề nào | C15: 1. Lớp HS đang tham gia chưa từng được giáo viên giao bất kỳ đề ôn thi nào (không có đề ở cả 2 mốc thời gian lọc) | D15: 1. Vào tab Ôn thi 2. Chọn tab 'Đề thầy cô giao' | F15: 2. Label hiển thị '0 đề', màn hình hiển thị text thông báo danh sách rỗng (vd: 'Chưa có đề nào được giao') kèm hình minh hoạ (nếu có), không hiển thị lỗi tải dữ liệu và không có card đề nào | G15: Medium | H15: GUI | I15: Pass | J15: Pass | L15: https://prnt.sc/yaS7bBFuAwcG
A16: =IF(I16>0,$B$3&"_"&SUBTOTAL(3,$I$9:I16),"") -> TC_APP_OnThi_DanhSachDe_6 | B16: Kiểm tra Dropdown Thời gian giao đề chỉ có đúng 2 lựa chọn | C16: 1. Đang ở màn Danh sách đề thầy cô giao | D16: 1. Bấm mở Dropdown Thời gian giao đề | F16: 1. Dropdown hiển thị đúng 2 lựa chọn: '2 tuần gần nhất' và '1 tháng gần nhất', không có lựa chọn khác | G16: Low | H16: GUI | I16: Pass | J16: Pass | L16: https://prnt.sc/vmPPNZ1zhMMJ
A17: 2. Card đề chưa nộp
A18: =IF(I18>0,$B$3&"_"&SUBTOTAL(3,$I$9:I18),"") -> TC_APP_OnThi_DanhSachDe_7 | B18: Kiểm tra Card đề chưa nộp hiển thị đầy đủ Tên đề, tiến độ x/y, thanh tiến độ và hạn nộp | C18: 1. HS được giao đề 'Đề kiểm tra giữa kỳ I - Unit 1-5' gồm 30 câu, đã làm dở 8/30 câu, hạn nộp 12/10 | D18: 1. Vào màn Danh sách đề thầy cô giao 2. Quan sát Card của đề 'Đề kiểm tra giữa kỳ I - Unit 1-5' | F18: 2. Card hiển thị đúng Tên đề 'Đề kiểm tra giữa kỳ I - Unit 1-5', tiến độ '8/30', thanh tiến độ tương ứng ~27%, hạn nộp '12/10', nút 'Làm tiếp' | G18: High | H18: Function | I18: Pass | J18: Pass | L18: https://prnt.sc/EtQWOwYveFyO
A19: =IF(I19>0,$B$3&"_"&SUBTOTAL(3,$I$9:I19),"") -> TC_APP_OnThi_DanhSachDe_8 | B19: Kiểm tra danh sách Card đề chưa nộp sắp xếp theo Ngày cô giao mới nhất lên đầu | C19: 1. Lớp HS đang tham gia có 3 đề chưa nộp, được giao vào 3 ngày khác nhau trong 2 tuần gần nhất | D19: 1. Vào màn Danh sách đề thầy cô giao 2. Quan sát thứ tự các Card trong danh sách | F19: 2. Các Card được sắp xếp theo thứ tự Ngày giáo viên giao đề giảm dần (đề giao mới nhất hiển thị trên cùng) | G19: High | H19: Function | I19: Pass | J19: Pass | L19: https://jiranew.codeinet.com/browse/PAR-3182
A20: =IF(I20>0,$B$3&"_"&SUBTOTAL(3,$I$9:I20),"") -> TC_APP_OnThi_DanhSachDe_9 | B20: Kiểm tra hiển thị nhãn '(QUÁ HẠN)' màu đỏ khi đề đã quá hạn nộp mà HS chưa nộp bài | C20: 1. HS được giao đề 'Đề kiểm tra 15 phút - Unit 4' có hạn nộp 09/10, ngày hiện tại sau 09/10 và HS chưa nộp bài | D20: 1. Vào màn Danh sách đề thầy cô giao 2. Quan sát dòng hạn nộp của Card đề 'Đề kiểm tra 15 phút - Unit 4' | F20: 2. Dòng hạn nộp hiển thị '09/10 (QUÁ HẠN)' với màu đỏ, nút hành động hiển thị 'Làm bài' | G20: High | H20: Function | I20: Pass | J20: Pass | L20: https://prnt.sc/9B6nsAOULh12
A21: =IF(I21>0,$B$3&"_"&SUBTOTAL(3,$I$9:I21),"") -> TC_APP_OnThi_DanhSachDe_10 | B21: Kiểm tra hiển thị nhãn '(Hôm nay)' khi hạn nộp đề đúng bằng ngày hiện tại | C21: 1. HS được giao 1 đề có hạn nộp trùng với ngày hệ thống hiện tại và HS chưa nộp bài | D21: 1. Vào màn Danh sách đề thầy cô giao 2. Quan sát dòng hạn nộp của đề có hạn nộp là hôm nay | F21: 2. Dòng hạn nộp hiển thị 'dd/mm (Hôm nay)' đúng định dạng, chưa hiển thị trạng thái quá hạn | G21: High | H21: Function | I21: Pass | J21: Pass | L21: https://prnt.sc/r9Kq_RNnUQiu
A22: =IF(I22>0,$B$3&"_"&SUBTOTAL(3,$I$9:I22),"") -> TC_APP_OnThi_DanhSachDe_11 | B22: Kiểm tra Card hiển thị nút 'Làm bài' khi HS chưa từng bắt đầu làm đề (0/y) | C22: 1. HS được giao 1 đề mới, chưa mở làm lần nào (tiến độ 0/10) | D22: 1. Vào màn Danh sách đề thầy cô giao 2. Quan sát Card của đề chưa từng làm | F22: 2. Card hiển thị tiến độ '0/10', thanh tiến độ rỗng, nút hành động hiển thị 'Làm bài' | G22: Medium | H22: Function | I22: Pass | J22: Pass | L22: https://prnt.sc/ljNcxv3N0zTg
A23: =IF(I23>0,$B$3&"_"&SUBTOTAL(3,$I$9:I23),"") -> TC_APP_OnThi_DanhSachDe_12 | B23: Kiểm tra Card hiển thị nút 'Làm tiếp' khi HS đã làm dở ít nhất 1 câu trong đề | C23: 1. HS được giao 1 đề, đã làm dở ít nhất 1 câu (vd 8/30), chưa nộp bài | D23: 1. Vào màn Danh sách đề thầy cô giao 2. Quan sát Card của đề đang làm dở | F23: 2. Card hiển thị nút hành động 'Làm tiếp' thay vì 'Làm bài' | G23: Medium | H23: GUI | I23: Pass | J23: Pass | L23: https://prnt.sc/IwS1dy-CDJzp
A24: =IF(I24>0,$B$3&"_"&SUBTOTAL(3,$I$9:I24),"") -> TC_APP_OnThi_DanhSachDe_13 | B24: Kiểm tra bấm nút 'Làm bài'/'Làm tiếp' chuyển đến màn Chi tiết đề tương ứng | C24: 1. Đang ở màn Danh sách đề thầy cô giao, có ít nhất 1 Card đề chưa nộp | D24: 1. Bấm nút 'Làm bài' (hoặc 'Làm tiếp') trên 1 Card đề bất kỳ | F24: 1. Hệ thống điều hướng đến màn Chi tiết đề đúng với đề vừa chọn | G24: High | H24: Function | I24: Pass | J24: Pass | L24: --Làm tiếp: https://prnt.sc/UZ_dvsgJvBOW https://prnt.sc/fTJTEeGcwT3Y --Làm bài: https://prnt.sc/EPClGXzW5SYi https://prnt.sc/t2LUWBSEDUut
A25: 3. Card đề đã nộp
A26: =IF(I26>0,$B$3&"_"&SUBTOTAL(3,$I$9:I26),"") -> TC_APP_OnThi_DanhSachDe_14 | B26: Kiểm tra Card đề đã nộp hiển thị đầy đủ khối điểm minh hoạ, Tên đề, x/y và điểm cao nhất | C26: 1. HS đã nộp đề 'Đề kiểm tra 15 phút - Unit 3' với kết quả 8/10 câu đúng, điểm cao nhất đạt được là 8.0 | D26: 1. Vào màn Danh sách đề thầy cô giao 2. Cuộn đến khu vực các đề đã nộp (mục 'Điểm') 3. Quan sát Card của đề 'Đề kiểm tra 15 phút - Unit 3' | F26: 3. Card hiển thị khối điểm minh hoạ, Tên đề 'Đề kiểm tra 15 phút - Unit 3', tỉ lệ '8/10', thanh tỉ lệ đúng/sai tương ứng, điểm cao nhất '8.0' | G26: High | H26: Function | I26: Pass | J26: Pass | L26: https://prnt.sc/L4bY_Y8Uuyym
A27: =IF(I27>0,$B$3&"_"&SUBTOTAL(3,$I$9:I27),"") -> TC_APP_OnThi_DanhSachDe_15 | B27: Kiểm tra thanh tỉ lệ đúng (xanh)/sai (đỏ) hiển thị đúng màu theo số câu đúng và sai | C27: 1. HS đã nộp 1 đề với kết quả 7 câu đúng, 3 câu sai trên tổng 10 câu | D27: 1. Vào màn Danh sách đề thầy cô giao, mục đề đã nộp 2. Quan sát thanh tỉ lệ trên Card | F27: 2. Thanh tỉ lệ hiển thị đoạn xanh tương ứng 7/10 và đoạn đỏ tương ứng 3/10 | G27: Medium | H27: GUI | I27: Pass | J27: Pass | L27: https://prnt.sc/gl4CJILqp8d3
A28: =IF(I28>0,$B$3&"_"&SUBTOTAL(3,$I$9:I28),"") -> TC_APP_OnThi_DanhSachDe_16 | B28: Kiểm tra điểm hiển thị trên Card là điểm của lần làm bài cao nhất khi HS làm lại nhiều lần | C28: 1. HS đã làm đề 3 lần với điểm số lần lượt 6.0, 9.0, 7.5 | D28: 1. Vào màn Danh sách đề thầy cô giao, mục đề đã nộp 2. Quan sát điểm hiển thị trên Card của đề đã làm 3 lần | F28: 2. Card hiển thị điểm '9.0' (điểm cao nhất trong 3 lần làm), không phải điểm của lần làm gần nhất | G28: High | H28: Function | I28: Pass | J28: Pass | L28: --Lần làm bài thứ 2: https://prnt.sc/drUJ1_nuFo3G https://prnt.sc/K2dEj3Clbkjq --Lần làm bài thứ 3 (điểm cao nhất): https://prnt.sc/8hKHpOTMoJVc https://prnt.sc/4bNuOm2t_VVE --Lần làm bài thứ 4: https://prnt.sc/KWrybMlG7j_1 https://prnt.sc/nSRsq8DFz-W7
A29: =IF(I29>0,$B$3&"_"&SUBTOTAL(3,$I$9:I29),"") -> TC_APP_OnThi_DanhSachDe_17 | B29: Kiểm tra bấm 'Xem bài đã làm' mở đúng màn Lịch sử làm bài của đề tương ứng | C29: 1. Đang ở màn Danh sách đề thầy cô giao, có ít nhất 1 Card đề đã nộp | D29: 1. Bấm 'Xem bài đã làm' trên Card đề đã nộp | F29: 1. Hệ thống mở màn Lịch sử làm bài đúng với đề vừa chọn, hiển thị danh sách các lần làm bài | G29: High | H29: Function | I29: Pass | J29: Pass | L29: https://prnt.sc/oE2fTXH0E5T7 https://prnt.sc/7z6tfQ3rJBKM https://prnt.sc/yYxKhgBPcvOi
A30: II. Rule hiển thị đề theo trạng thái công khai trên CMS
A31: 1. Công khai / Chưa công khai / Ẩn / Xoá đề
A32: =IF(I32>0,$B$3&"_"&SUBTOTAL(3,$I$9:I32),"") -> TC_APP_OnThi_DanhSachDe_18 | B32: Kiểm tra đề ở trạng thái Công khai trên CMS hiển thị trong danh sách đề | C32: 1. Giáo viên đã giao 1 đề cho lớp HS, đề đang ở trạng thái Công khai trên CMS | D32: 1. Vào màn Danh sách đề thầy cô giao | F32: 1. Đề Công khai hiển thị bình thường trong danh sách | G32: High | H32: Function | I32: Pass | J32: Pass | L32: https://prnt.sc/IyoIgKJxAQnh
A33: =IF(I33>0,$B$3&"_"&SUBTOTAL(3,$I$9:I33),"") -> TC_APP_OnThi_DanhSachDe_19 | B33: Kiểm tra đề ở trạng thái Chưa công khai trên CMS không hiển thị trong danh sách đề | C33: 1. Giáo viên đã giao 1 đề cho lớp HS nhưng đề đang ở trạng thái Chưa công khai trên CMS | D33: 1. Vào màn Danh sách đề thầy cô giao | F33: 1. Đề Chưa công khai không xuất hiện trong danh sách đề trên App/Web, kể cả khi đã nằm trong khoảng thời gian lọc | G33: High | H33: Function | I33: Pass | J33: Pass | L33: https://prnt.sc/6_RUdkcD8b7z https://prnt.sc/xa1j5K6tV4uy
A34: =IF(I34>0,$B$3&"_"&SUBTOTAL(3,$I$9:I34),"") -> TC_APP_OnThi_DanhSachDe_20 | B34: Kiểm tra HS đang làm dở đề mà giáo viên Ẩn đề giữa chừng vẫn tiếp tục làm và nhận được kết quả | C34: 1. HS đang trong màn làm bài của 1 đề (đã trả lời một số câu, chưa nộp) 2. Giáo viên chuyển đề này sang trạng thái Chưa công khai trên CMS ngay trong lúc HS đang làm | D34: 1. HS tiếp tục làm hết các câu còn lại trong đề 2. HS bấm Nộp bài | F34: 1. HS làm bài bình thường, không bị gián đoạn hay chặn 2. Hệ thống chấm và trả kết quả bình thường cho lần làm này | G34: High | H34: Function | I34: Pass | J34: Pass
A35: =IF(I35>0,$B$3&"_"&SUBTOTAL(3,$I$9:I35),"") -> TC_APP_OnThi_DanhSachDe_21 | B35: Kiểm tra đề bị Ẩn giữa chừng sau khi HS đã nộp bài vẫn hiển thị trên App nếu Web vẫn đang hiển thị đề đó | C35: 1. HS vừa hoàn thành và nộp bài một đề đã bị giáo viên Ẩn (chuyển Chưa công khai) trong lúc đang làm 2. Trên Web, đề này vẫn đang hiển thị trong danh sách đề đã giao (giáo viên chưa ẩn hẳn khỏi Web) | D35: 1. Kiểm tra danh sách đề đã giao trên Web đối với đề vừa bị Ẩn 2. Quay lại màn Danh sách đề thầy cô giao trên App | F35: 1. Web vẫn hiển thị đề đã bị Ẩn trong danh sách đề đã giao 2. App cũng vẫn hiển thị đề vừa nộp ở mục đề đã nộp, đồng bộ đúng với trạng thái đang hiển thị trên Web, kèm điểm số/kết quả của lần làm vừa nộp | G35: High | H35: Function | I35: Pass | J35: Pass
A36: =IF(I36>0,$B$3&"_"&SUBTOTAL(3,$I$9:I36),"") -> TC_APP_OnThi_DanhSachDe_22 | B36: Kiểm tra giáo viên Xoá đề thi trên CMS làm biến mất toàn bộ hiển thị và lịch sử làm bài phía HS | C36: 1. HS đã từng làm và nộp bài 1 đề, đề này sau đó bị giáo viên Xoá khỏi CMS | D36: 1. Vào màn Danh sách đề thầy cô giao 2. Kiểm tra màn Lịch sử làm bài liên quan đến đề đã bị xoá (nếu còn truy cập được từ nơi khác) | F36: 1. Đề đã bị xoá không còn xuất hiện trong danh sách đề 2. Toàn bộ lịch sử làm bài của đề đã xoá cũng không còn truy cập được | G36: High | H36: Function | I36: Pass | J36: Pass | L36: --Trước xóa: https://prnt.sc/NlSkfuFLwE5d https://prnt.sc/8oIzuINcScXK https://prnt.sc/FNioLOL7qoFl https://prnt.sc/XYNu5r8PRB35 --Sau xóa: https://prnt.sc/oxezikEXisf2 https://prnt.sc/2gfLN4oXboPa https://prnt.sc/k8tF_NG4_o2V
A37: III. Rule quyền truy cập theo gói dịch vụ
A38: 1. Đề Free
A39: =IF(I39>0,$B$3&"_"&SUBTOTAL(3,$I$9:I39),"") -> TC_APP_OnThi_DanhSachDe_23 | B39: Kiểm tra mọi loại tài khoản (Free/Pro/Dùng thử) đều làm được đề Free | C39: 1. Lớp HS được giao 1 đề Free 2. Lần lượt kiểm tra với tài khoản Free, Pro, Dùng thử | D39: 1. Bấm 'Làm bài' trên Card đề Free với từng loại tài khoản | F39: 1. Cả 3 loại tài khoản đều vào được màn làm bài và làm đề Free bình thường, không bị chặn | G39: High | H39: Function | I39: Pass | J39: Todo | L39: --Tài khoản pro/ dùng thử: https://prnt.sc/tpoLcN1q0VSg https://prnt.sc/ebhd7PUOmm5a --Tài khoản thường/ hết hạn: https://prnt.sc/zB89WFq5V-bC https://prnt.sc/-CF0FCz-d_DY
A40: =IF(I40>0,$B$3&"_"&SUBTOTAL(3,$I$9:I40),"") -> TC_APP_OnThi_DanhSachDe_24 | B40: Kiểm tra tài khoản Free bị chặn chức năng Làm lại đối với đề Free đã nộp | C40: 1. Tài khoản Free đã nộp bài 1 đề Free | D40: 1. Vào màn Danh sách đề thầy cô giao, mục đề đã nộp 2. Mở Card đề Free vừa nộp 3. Tìm và bấm chức năng Làm lại (nếu có hiển thị) | F40: 3. Chức năng Làm lại không khả dụng hoặc bị chặn với tài khoản Free (không cho làm lại đề Free) | G40: Medium | H40: Function | I40: Pass | J40: Todo | L40: https://prnt.sc/dkMNK44D5UmQ https://prnt.sc/hQi8rY17u7u2
...

Sheet Summary TCs
C1: [Link CMS / hệ thống test] | F1: [Tên dự án]
C3: Categories | D3: Test Case Overview
B4: STT | D4: #TC | E4: Pass | F4: Fail | G4: N/A | H4: Pending | I4: Todo | J4: Status Test | K4: Người test | L4: Note
D5: =D7 -> 84 | E5: =E7 -> 71 | F5: =F7 -> 0 | G5: =G7 -> 0 | H5: =H7 -> 1 | I5: =I7 -> 12
B6: 1 | C6: Danh sách đề (Đề thầy cô giao) | D6: ='Danh sách đề (Đề thầy cô giao)'!A5 -> 84 | E6: ='Danh sách đề (Đề thầy cô giao)'!B5 -> 71 | F6: ='Danh sách đề (Đề thầy cô giao)'!C5 -> 0 | G6: ='Danh sách đề (Đề thầy cô giao)'!D5 -> 0 | H6: ='Danh sách đề (Đề thầy cô giao)'!E5 -> 1 | I6: ='Danh sách đề (Đề thầy cô giao)'!F5 -> 12 | J6: Todo
C7: Total | D7: =SUM(D6:D6) -> 84 | E7: =SUM(E6:E6) -> 71 | F7: =SUM(F6:F6) -> 0 | G7: =SUM(G6:G6) -> 0 | H7: =SUM(H6:H6) -> 1 | I7: =SUM(I6:I6) -> 12
C8: % | E8: =IFERROR(E7/D7,0) -> 0.8452381 | F8: =IFERROR(F7/D7,0) -> 0 | G8: =IFERROR(G7/D7,0) -> 0 | H8: =IFERROR(H7/D7,0) -> 0.011904762 | I8: =IFERROR(I7/D7,0) -> 0.14285714

Sheet Glossary
B1: STT | C1: Phân loại | D1: Thật ngữ sử dụng | E1: Giải nghĩa | F1: Đối tượng sử dụng | G1: Ghi chú
B2: 1 | D2: Status Test | E2: Trạng thái test | F2: QA/QC/Tester
B3: =B2+B2 -> 2 | C3: Status Test | D3: Todo | E3: Sẵn sàng test | F3: QA/QC/Tester
B4: =B3+1 -> 3 | D4: Doing | E4: Đang test | F4: QA/QC/Tester
B5: =B4+1 -> 4 | D5: Pass | E5: Đã pass | F5: QA/QC/Tester
B6: =B5+1 -> 5 | D6: Fail | E6: Có lỗi - log lỗi | F6: QA/QC/Tester
B7: =B6+1 -> 6 | D7: Pending | E7: Dừng test do chưa đủ điều kiện, dữ kiện/ kịch bản thiết sót/ chờ xác nhận | F7: QA/QC/Tester
B8: =B7+1 -> 7 | D8: Re-Test | E8: Cần test lại sau quá trình Dev fixed | F8: QA/QC/Tester
B9: =B8+1 -> 8 | D9: N/A | E9: Không test - do không trong scope test | F9: QA/QC/Tester
B10: =B9+1 -> 9 | D10: Priority | E10: Mức độ ưu tiên của test case | F10: QA/QC/Tester
B11: =B10+1 -> 10 | C11: Priority | D11: High | E11: Là những TCs là chức năng chính và happy cases | F11: QA/QC/Tester
B12: =B11+1 -> 11 | D12: Medium | E12: Là những TCs là chức năng validate | F12: QA/QC/Tester
B13: =B12+1 -> 12 | D13: Low | E13: Là những TCs là check giao diện | F13: QA/QC/Tester
B14: =B13+1 -> 13 | D14: Precondition | E14: Tiền điều kiện - Điều kiện này cần có để thực hiện được ý nghĩa test case đưa ra | F14: QA/QC/Tester
B15: =B14+1 -> 14 | D15: Test data | E15: Dữ liệu nhập vào test - tương ứng với mỗi trường thông tin | F15: QA/QC/Tester
B16: =B15+1 -> 15 | D16: Untested | E16: Chưa được kiểm tra | F16: QA/QC/Tester
B17: =B16+1 -> 16 | D17: Next Release/Next Version | E17: Phiên bản tiếp theo | F17: QA/QC/Tester/Dev
B18: =B17+1 -> 17 | D18: Resolved | E18: Đã giải quyết - thường dùng diễn đạt những Q&A đã giải quyết | F18: QA/QC/Tester/Dev
B19: =B18+1 -> 18 | D19: Validate | E19: Kiểm tra xác nhận hợp lệ - không hợp lệ ; Xác nhận với mỗi field | F19: QA/QC/Tester/Dev
B20: =B19+1 -> 19
B21: =B20+1 -> 20
B22: =B21+1 -> 21

Sheet  Data
C1: Status | E1: Priority | F1: TC Type
C2: Todo | E2: High | F2: Function
C3: Doing | E3: Medium | F3: GUI
C4: Pass | E4: Low | F4: Others
C5: Fail
C6: Pending
C7: Re-Test
C8: N/A
